Workbook

Sheet 453 Prompts
A1: 453 Cleaned PTE Write Essay Prompts (3-Model Verified)
A2: Each prompt is verified by 3 Local LLMs (Gemma 4, Qwen 3, DeepSeek-R1) with single task type and up to 3 topic tags.
A4: No. | B4: Cleaned PTE-style prompt | C4: Task type | D4: Primary topic | E4: Secondary topic 1 | F4: Secondary topic 2
A5: 1 | B5: “The only thing that interferes with my learning is education.” – Albert Einstein. What did he mean by that? Do you think he is correct? | C5: To what extent do you agree or disagree | D5: Education
A6: 2 | B6: A healthy diet is more effective for keeping fit than exercise. What is your opinion? | C6: To what extent do you agree or disagree | D6: Food and health
A7: 3 | B7: A healthy diet is more important for keeping fit than exercise. To what extent do you agree with this statement? Give an example or personal experiences. | C7: To what extent do you agree or disagree | D7: Food and health
A8: 4 | B8: Advertisements make people purchase things they don’t need or cannot afford, but they also convey information to increase people's life quality. What is your opinion? | C8: To what extent do you agree or disagree | D8: Media and communication
A9: 5 | B9: As cities expand, governments should look forward to creating better networks of public transport available for everyone rather than building more roads for vehicle owning population. To what extent do you agree or disagree? | C9: To what extent do you agree or disagree | D9: City development | E9: Government, politics, and diplomacy | F9: City development
A10: 6 | B10: As national services, which one deserves to receive more financial support, education or health? | C10: others | D10: Government, politics, and diplomacy | E10: Food and health | F10: Economy, money, and trade
A11: 7 | B11: Because university degrees can get people jobs with higher salaries, university students should pay full cost for their education. Do you agree or not? | C11: To what extent do you agree or disagree | D11: Education | E11: Economy, money, and trade
A12: 8 | B12: Some people believe that all cities and towns should have at least one large public open space. To what extent do you agree or disagree? | C12: To what extent do you agree or disagree | D12: City development | E12: Environment | F12: Lifestyle
A13: 9 | B13: Climate change is a concerning global issue. Who has the main responsibility to take action to solve this problem, governments, large companies, or individuals? | C13: others | D13: Climate | E13: Environment
A14: 10 | B14: Communication has changed significantly in the last 10 years. Discuss the positive and negative impacts of this change. | C14: others | D14: Media and communication
A15: 11 | B15: Culture shock is a new worry leading to less immigration. What are the possible options to eradicate this issue? | C15: others | D15: Socio-cultural and global issues
A16: 12 | B16: Some people work long hours to achieve success, but others feel that we should spend more free time for fun than for money. Which lifestyle do you prefer? Explain your opinion. | C16: others | D16: Lifestyle | E16: Leisure, sports, and hobbies | F16: Work
A17: 13 | B17: Do you believe that the industrial revolution was the main factor for problems in developed nations? | C17: To what extent do you agree or disagree | D17: Economy, money, and trade
A18: 14 | B18: Do you think consumers should avoid over-packaged products or is it the responsibility of manufacturers to avoid extra packaging? Give your views or any relevant examples based on your own experience. | C18: others | D18: Environment
A19: 15 | B19: Do you think it has a positive or negative impact on you if you buy a home close to the workplace? | C19: Is it a positive or negative development | D19: Lifestyle
A20: 16 | B20: For children, using films to study is as important as studying literature. To what extent do you agree? | C20: To what extent do you agree or disagree | D20: Education
A21: 17 | B21: Many education systems assess students' learning using formal written examinations. Those kinds of exams are a valid method. To what extent do you agree or disagree? Give examples with your own experience. | C21: To what extent do you agree or disagree | D21: Education
A22: 18 | B22: 'In a war of ideas, it is people who get killed'. Does a common man suffer from a group’s ideology? Express your opinion and support the same with reasons and examples. | C22: To what extent do you agree or disagree | D22: Socio-cultural and global issues | E22: Ethics | F22: Government, politics, and diplomacy
A23: 19 | B23: In many countries, the birth rates are lowering, and the problems of an ageing population are serious. What are the causes and the effects of this phenomenon? what should we do to address these issues? | C23: causes-problems-solutions | D23: Population | E23: Age, generation, and gender
A24: 20 | B24: In some countries around the world, voting is compulsory. Do you agree with the notion of compulsory voting? | C24: To what extent do you agree or disagree | D24: Government, politics, and diplomacy
A25: 21 | B25: In the 18th century due to industrialization, a lot of people migrated to developed countries. This affected lifestyle and increased problems in developed countries. What is your opinion about this? | C25: To what extent do you agree or disagree | D25: Population
A26: 22 | B26: In the past 100 years, there have been many inventions such as antibiotics, airplanes and computers. What do you think is the most important one? Why? | C26: To what extent do you agree or disagree | D26: Science, technology, and innovation
A27: 23 | B27: In your opinion, what are the advantages and disadvantages of extreme or adventure sports? | C27: Do the advantages outweigh the disadvantages | D27: Leisure, sports, and hobbies
A28: 24 | B28: The information revolution brought about by modern mass communications has both positive and negative consequences for individuals and society. To what extent do you agree with this statement? Give the reason with your own experience. | C28: To what extent do you agree or disagree | D28: Media and communication
A29: 25 | B29: Is a competitive environment in school or university good or bad? Discuss and give your own experiences as examples. | C29: others | D29: Education | E29: Leisure, sports, and hobbies
A30: 26 | B30: Is education as important to learn life values and ethics as to learn practical skills for future development? | C30: To what extent do you agree or disagree | D30: Education
A31: 27 | B31: It is argued that getting married before finishing studying or getting established in a good job is foolish. To what extent do you agree or disagree? | C31: To what extent do you agree or disagree | D31: Socio-cultural and global issues | E31: Work | F31: Education
A32: 28 | B32: It is important to preserve the beautiful buildings of the past, even if it will be expensive to do so. To what extent do you agree or disagree with it. | C32: To what extent do you agree or disagree | D32: Art and museums
A33: 29 | B33: In our technological world, the number of new inventions has been increasing. Please make an example with its impact on our life, and explain if it is beneficial or detrimental. | C33: others | D33: Science, technology, and innovation
A34: 30 | B34: In many towns and cities large shopping malls are replacing small local shops. Do you think this is a positive development? Give your reasons and examples. | C34: To what extent do you agree or disagree | D34: Economy, money, and trade | E34: Lifestyle | F34: City development
A35: 31 | B35: Learning a new language at an early age is helpful for children. It is more positive for their future prospects, though it can also have some adverse effects. Do you agree or disagree? | C35: To what extent do you agree or disagree | D35: Education | E35: Language | F35: Age, generation, and gender
A36: 32 | B36: Many people are living in poor lifestyles which affect their health. List some unhealthy lifestyles and give some solution suggestions to the national health service. | C36: others | D36: Food and health | E36: Lifestyle
A37: 33 | B37: Many people choose to emigrate to other countries. What are the advantages and disadvantages of living in a foreign country? Discuss with your own experience. | C37: Do the advantages outweigh the disadvantages | D37: Socio-cultural and global issues
A38: 34 | B38: Many workers like nurses and teachers should get more pay, especially in recent years when people in finance，film actors and company leaders are paid a larger amount of money. To what extent do you agree or disagree with the above statement and what’s your opinion? | C38: To what extent do you agree or disagree | D38: Economy, money, and trade | E38: Food and health | F38: Leisure, sports, and hobbies
A39: 35 | B39: The mass media, such as TV, radio and newspapers, have an influence on people, particularly on younger generations. It plays a pivotal role in shaping the opinions of people, especially teenagers and young people. To what extent do you agree with this? Please give examples. | C39: To what extent do you agree or disagree | D39: Media and communication | E39: Age, generation, and gender
A40: 36 | B40: Most high-level jobs are done by men. Should governments reserve a certain percentage of these jobs for women? | C40: To what extent do you agree or disagree | D40: Age, generation, and gender | E40: Government, politics, and diplomacy | F40: Work
A41: 37 | B41: Now doctors can talk to patients by using internet-based communication in the office. Discuss the advantages and disadvantages. | C41: Do the advantages outweigh the disadvantages | D41: Science, technology, and innovation
...

Sheet Topic Statistics
A1: Topic Statistics – Weighted Primary/Secondary Model | J1: Model inputs
A2: Primary topic weight = 1.0; each secondary topic weight = 0.5. Weighted score = Primary count + 0.5 × Secondary count. | J2: Primary-topic weight | K2: 1
J3: Secondary-topic weight | K3: 0.5
A4: Rank | B4: Topic | C4: Primary count | D4: Secondary count | E4: Weighted score | F4: Weighted share | G4: Raw coverage count | H4: Raw coverage % | J4: Number of prompts | K4: 453
A5: 1 | B5: Education | C5: =COUNTIF('453 Prompts'!$D$5:$D$457, B5) | D5: =COUNTIF('453 Prompts'!$E$5:$E$457, B5) + COUNTIF('453 Prompts'!$F$5:$F$457, B5) | E5: =C5*$K$2 + D5*$K$3 | F5: =E5/$E$27 | G5: =C5+D5 | H5: =G5/$K$4
A6: 2 | B6: Socio-cultural and global issues | C6: =COUNTIF('453 Prompts'!$D$5:$D$457, B6) | D6: =COUNTIF('453 Prompts'!$E$5:$E$457, B6) + COUNTIF('453 Prompts'!$F$5:$F$457, B6) | E6: =C6*$K$2 + D6*$K$3 | F6: =E6/$E$27 | G6: =C6+D6 | H6: =G6/$K$4 | J6: Key results
A7: 3 | B7: Science, technology, and innovation | C7: =COUNTIF('453 Prompts'!$D$5:$D$457, B7) | D7: =COUNTIF('453 Prompts'!$E$5:$E$457, B7) + COUNTIF('453 Prompts'!$F$5:$F$457, B7) | E7: =C7*$K$2 + D7*$K$3 | F7: =E7/$E$27 | G7: =C7+D7 | H7: =G7/$K$4 | J7: Primary assignments | K7: =C27
A8: 4 | B8: Media and communication | C8: =COUNTIF('453 Prompts'!$D$5:$D$457, B8) | D8: =COUNTIF('453 Prompts'!$E$5:$E$457, B8) + COUNTIF('453 Prompts'!$F$5:$F$457, B8) | E8: =C8*$K$2 + D8*$K$3 | F8: =E8/$E$27 | G8: =C8+D8 | H8: =G8/$K$4 | J8: Secondary assignments | K8: =D27
A9: 5 | B9: Lifestyle | C9: =COUNTIF('453 Prompts'!$D$5:$D$457, B9) | D9: =COUNTIF('453 Prompts'!$E$5:$E$457, B9) + COUNTIF('453 Prompts'!$F$5:$F$457, B9) | E9: =C9*$K$2 + D9*$K$3 | F9: =E9/$E$27 | G9: =C9+D9 | H9: =G9/$K$4 | J9: Total weighted score | K9: =E27
A10: 6 | B10: Work | C10: =COUNTIF('453 Prompts'!$D$5:$D$457, B10) | D10: =COUNTIF('453 Prompts'!$E$5:$E$457, B10) + COUNTIF('453 Prompts'!$F$5:$F$457, B10) | E10: =C10*$K$2 + D10*$K$3 | F10: =E10/$E$27 | G10: =C10+D10 | H10: =G10/$K$4 | J10: Average topics per prompt | K10: =(C27+D27)/K4
A11: 7 | B11: Environment | C11: =COUNTIF('453 Prompts'!$D$5:$D$457, B11) | D11: =COUNTIF('453 Prompts'!$E$5:$E$457, B11) + COUNTIF('453 Prompts'!$F$5:$F$457, B11) | E11: =C11*$K$2 + D11*$K$3 | F11: =E11/$E$27 | G11: =C11+D11 | H11: =G11/$K$4 | J11: Average weighted units per prompt | K11: =E27/K4
A12: 8 | B12: Economy, money, and trade | C12: =COUNTIF('453 Prompts'!$D$5:$D$457, B12) | D12: =COUNTIF('453 Prompts'!$E$5:$E$457, B12) + COUNTIF('453 Prompts'!$F$5:$F$457, B12) | E12: =C12*$K$2 + D12*$K$3 | F12: =E12/$E$27 | G12: =C12+D12 | H12: =G12/$K$4
A13: 9 | B13: Age, generation, and gender | C13: =COUNTIF('453 Prompts'!$D$5:$D$457, B13) | D13: =COUNTIF('453 Prompts'!$E$5:$E$457, B13) + COUNTIF('453 Prompts'!$F$5:$F$457, B13) | E13: =C13*$K$2 + D13*$K$3 | F13: =E13/$E$27 | G13: =C13+D13 | H13: =G13/$K$4
A14: 10 | B14: Food and health | C14: =COUNTIF('453 Prompts'!$D$5:$D$457, B14) | D14: =COUNTIF('453 Prompts'!$E$5:$E$457, B14) + COUNTIF('453 Prompts'!$F$5:$F$457, B14) | E14: =C14*$K$2 + D14*$K$3 | F14: =E14/$E$27 | G14: =C14+D14 | H14: =G14/$K$4
A15: 11 | B15: Leisure, sports, and hobbies | C15: =COUNTIF('453 Prompts'!$D$5:$D$457, B15) | D15: =COUNTIF('453 Prompts'!$E$5:$E$457, B15) + COUNTIF('453 Prompts'!$F$5:$F$457, B15) | E15: =C15*$K$2 + D15*$K$3 | F15: =E15/$E$27 | G15: =C15+D15 | H15: =G15/$K$4
A16: 12 | B16: City development | C16: =COUNTIF('453 Prompts'!$D$5:$D$457, B16) | D16: =COUNTIF('453 Prompts'!$E$5:$E$457, B16) + COUNTIF('453 Prompts'!$F$5:$F$457, B16) | E16: =C16*$K$2 + D16*$K$3 | F16: =E16/$E$27 | G16: =C16+D16 | H16: =G16/$K$4
A17: 13 | B17: Ethics | C17: =COUNTIF('453 Prompts'!$D$5:$D$457, B17) | D17: =COUNTIF('453 Prompts'!$E$5:$E$457, B17) + COUNTIF('453 Prompts'!$F$5:$F$457, B17) | E17: =C17*$K$2 + D17*$K$3 | F17: =E17/$E$27 | G17: =C17+D17 | H17: =G17/$K$4
A18: 14 | B18: Government, politics, and diplomacy | C18: =COUNTIF('453 Prompts'!$D$5:$D$457, B18) | D18: =COUNTIF('453 Prompts'!$E$5:$E$457, B18) + COUNTIF('453 Prompts'!$F$5:$F$457, B18) | E18: =C18*$K$2 + D18*$K$3 | F18: =E18/$E$27 | G18: =C18+D18 | H18: =G18/$K$4
A19: 15 | B19: Population | C19: =COUNTIF('453 Prompts'!$D$5:$D$457, B19) | D19: =COUNTIF('453 Prompts'!$E$5:$E$457, B19) + COUNTIF('453 Prompts'!$F$5:$F$457, B19) | E19: =C19*$K$2 + D19*$K$3 | F19: =E19/$E$27 | G19: =C19+D19 | H19: =G19/$K$4
A20: 16 | B20: Crime, punishment, and law | C20: =COUNTIF('453 Prompts'!$D$5:$D$457, B20) | D20: =COUNTIF('453 Prompts'!$E$5:$E$457, B20) + COUNTIF('453 Prompts'!$F$5:$F$457, B20) | E20: =C20*$K$2 + D20*$K$3 | F20: =E20/$E$27 | G20: =C20+D20 | H20: =G20/$K$4
A21: 17 | B21: Travelling and tourism | C21: =COUNTIF('453 Prompts'!$D$5:$D$457, B21) | D21: =COUNTIF('453 Prompts'!$E$5:$E$457, B21) + COUNTIF('453 Prompts'!$F$5:$F$457, B21) | E21: =C21*$K$2 + D21*$K$3 | F21: =E21/$E$27 | G21: =C21+D21 | H21: =G21/$K$4
A22: 18 | B22: Climate | C22: =COUNTIF('453 Prompts'!$D$5:$D$457, B22) | D22: =COUNTIF('453 Prompts'!$E$5:$E$457, B22) + COUNTIF('453 Prompts'!$F$5:$F$457, B22) | E22: =C22*$K$2 + D22*$K$3 | F22: =E22/$E$27 | G22: =C22+D22 | H22: =G22/$K$4
A23: 19 | B23: Language | C23: =COUNTIF('453 Prompts'!$D$5:$D$457, B23) | D23: =COUNTIF('453 Prompts'!$E$5:$E$457, B23) + COUNTIF('453 Prompts'!$F$5:$F$457, B23) | E23: =C23*$K$2 + D23*$K$3 | F23: =E23/$E$27 | G23: =C23+D23 | H23: =G23/$K$4
... A26: 22 | B26: Traffic | C26: =COUNTIF('453 Prompts'!$D$5:$D$457, B26) | D26: =COUNTIF('453 Prompts'!$E$5:$E$457, B26) + COUNTIF('453 Prompts'!$F$5:$F$457, B26) | E26: =C26*$K$2 + D26*$K$3 | F26: =E26/$E$27 | G26: =C26+D26 | H26: =G26/$K$4
A27: Total | C27: =SUM(C5:C26) | D27: =SUM(D5:D26) | E27: =SUM(E5:E26) | F27: =SUM(F5:F26) | G27: =SUM(G5:G26) | H27: =E27/$K$4

Sheet Task Type Statistics
A1: Task Type Statistics – Single-Label Classification
A2: Each of the 453 prompts is assigned to exactly one task type.
A4: Rank | B4: Task type | C4: Count | D4: Percentage
A5: 1 | B5: To what extent do you agree or disagree | C5: =COUNTIF('453 Prompts'!$C$5:$C$457, B5) | D5: =C5/$C$11
A6: 2 | B6: others | C6: =COUNTIF('453 Prompts'!$C$5:$C$457, B6) | D6: =C6/$C$11
A7: 3 | B7: Do the advantages outweigh the disadvantages | C7: =COUNTIF('453 Prompts'!$C$5:$C$457, B7) | D7: =C7/$C$11
A8: 4 | B8: Is it a positive or negative development | C8: =COUNTIF('453 Prompts'!$C$5:$C$457, B8) | D8: =C8/$C$11
A9: 5 | B9: causes-problems-solutions | C9: =COUNTIF('453 Prompts'!$C$5:$C$457, B9) | D9: =C9/$C$11
A10: 6 | B10: Discuss both views and give your opinions | C10: =COUNTIF('453 Prompts'!$C$5:$C$457, B10) | D10: =C10/$C$11
A11: Total | C11: =SUM(C5:C10) | D11: =SUM(D5:D10)
